Workbook

Sheet Cover
B1: PROJECT MERIDIAN
B3: UK Value-Add Multifamily — JV Acquisition & Business Plan
B4: 120-unit Build-to-Rent · value-add · 5-year hold · LP/GP joint venture with promote · GBP
B6: THE DEAL
C7: A sponsor acquires a 120-unit UK residential block at £22.0m, under-rented and tired. Over a five-year hold the plan is to renovate all units to a £250/month rent premium, lift occupancy to 95%, refinance in Year 3 to return capital, and exit on a compressed yield. It is funded by a JV: an institutional LP (90%) and the sponsor GP (10%), with profits split through a two-tier promote over an 8% preferred return. This model runs the property cash flow, the debt and refinance, and the full distribution waterfall, and states an IC recommendation.
B13: CONTENTS
B14: 1 | C14: Assumptions | E14: Deal inputs (blue)
B15: 2 | C15: Property Model | E15: Operating cash flow, renovation, debt, refinance, exit, property & levered returns
B16: 3 | C16: JV Waterfall | E16: LP/GP distribution waterfall — return of capital, 8% pref, two-tier promote
B17: 4 | C17: IC Summary | E17: Sources & uses, business plan, returns, sensitivity, recommendation
B19: THE WATERFALL (how profits are split)
C20: 1. Return of capital — pro-rata (LP 90% / GP 10%).
C21: 2. 8% preferred return — pro-rata, until the LP earns an 8% IRR.
C22: 3. 80/20 (LP/GP) — until the LP reaches a 15% IRR (GP's first promote tier).
C23: 4. 70/30 (LP/GP) — above a 15% LP IRR (GP's second promote tier).
B25: NOTES
B26: • | C26: Interest is charged on opening balances; annual cash flows. Illustrative UK BTR parameters; no real asset or client data.
B27: • | C27: The waterfall uses accrual (hurdle) accounts for the 8% and 15% IRR hurdles — a standard, transparent method. Not investment advice.

Sheet Assumptions
B1: PROJECT MERIDIAN | Deal Assumptions
B3: UK value-add multifamily (BTR). Blue = input. GBP.
B4: ASSET & ACQUISITION
B5: Number of units | C5: 120
B6: Purchase price | C6: 22000000 | D6: £183k/unit
B7: Acquisition costs (% of price) | C7: 0.05
B8: Renovation cost per unit | C8: 22000
B10: RENT & OPERATIONS
B11: In-place rent (£/unit/month) | C11: 1150
B12: Renovated rent (£/unit/month) | C12: 1400 | D12: +£250 premium
B13: Rental growth (p.a.) | C13: 0.03
B14: Operating expenses (% of EGI) | C14: 0.3
B16: Renovated units (start of year, Yr1-5) | D16: 0 | E16: 60 | F16: 120 | G16: 120 | H16: 120
B17: Occupancy (Yr1-5) | D17: 0.9 | E17: 0.92 | F17: 0.95 | G17: 0.95 | H17: 0.95
B19: DEBT & REFINANCE
B20: Senior loan (% of total cost, LTC) | C20: 0.6
B21: Senior interest rate | C21: 0.06
B22: Refinance year | C22: 3
B23: Refi valuation yield (stabilised) | C23: 0.0475
B24: Refi loan-to-value | C24: 0.65
B25: Refi interest rate | C25: 0.0575
B27: EXIT
B28: Exit yield (cap rate) | C28: 0.045
B29: Selling costs (% of value) | C29: 0.015
B31: JV WATERFALL
B32: LP share of equity | C32: 0.9
B33: GP share of equity | C33: 0.1
B34: Preferred return (LP IRR hurdle 1) | C34: 0.08
B35: Second hurdle (LP IRR) | C35: 0.15
B36: GP promote — tier 1 (pref to hurdle 2) | C36: 0.2 | D36: 80/20 LP/GP
B37: GP promote — tier 2 (above hurdle 2) | C37: 0.3 | D37: 70/30 LP/GP

Sheet Property Model
B1: PROJECT MERIDIAN | Property Cash Flow, Debt & Returns
B3: GBP. Blue=input · black=formula · green=link. Renovation phased Yr1-2; refinance end Yr3; exit Yr5.
C4: Year 0 | D4: Year 1 | E4: Year 2 | F4: Year 3 | G4: Year 4 | H4: Year 5 | I4: Year 6
B6: OPERATING CASH FLOW
B7: In-place rent (£/unit/mo) | D7: =Assumptions!$C$11 -> 1150 | E7: =D7*(1+Assumptions!$C$13) -> 1184.5 | F7: =E7*(1+Assumptions!$C$13) -> 1220.035 | G7: =F7*(1+Assumptions!$C$13) -> 1256.6361 | H7: =G7*(1+Assumptions!$C$13) -> 1294.3351 | I7: =H7*(1+Assumptions!$C$13) -> 1333.1652
B8: Renovated rent (£/unit/mo) | D8: =Assumptions!$C$12 -> 1400 | E8: =D8*(1+Assumptions!$C$13) -> 1442 | F8: =E8*(1+Assumptions!$C$13) -> 1485.26 | G8: =F8*(1+Assumptions!$C$13) -> 1529.8178 | H8: =G8*(1+Assumptions!$C$13) -> 1575.7123 | I8: =H8*(1+Assumptions!$C$13) -> 1622.9837
B9: Renovated units (start of yr) | D9: =Assumptions!D16 -> 0 | E9: =Assumptions!E16 -> 60 | F9: =Assumptions!F16 -> 120 | G9: =Assumptions!G16 -> 120 | H9: =Assumptions!H16 -> 120 | I9: =Assumptions!H16 -> 120
B10: Un-renovated units | D10: =Assumptions!$C$5-D9 -> 120 | E10: =Assumptions!$C$5-E9 -> 60 | F10: =Assumptions!$C$5-F9 -> 0 | G10: =Assumptions!$C$5-G9 -> 0 | H10: =Assumptions!$C$5-H9 -> 0 | I10: =Assumptions!$C$5-I9 -> 0
B11: Gross potential rent | D11: =(D9*D8+D10*D7)*12 -> 1656000 | E11: =(E9*E8+E10*E7)*12 -> 1891080 | F11: =(F9*F8+F10*F7)*12 -> 2138774.4 | G11: =(G9*G8+G10*G7)*12 -> 2202937.6 | H11: =(H9*H8+H10*H7)*12 -> 2269025.8 | I11: =(I9*I8+I10*I7)*12 -> 2337096.5
B12: Occupancy | D12: =Assumptions!D17 -> 0.9 | E12: =Assumptions!E17 -> 0.92 | F12: =Assumptions!F17 -> 0.95 | G12: =Assumptions!G17 -> 0.95 | H12: =Assumptions!H17 -> 0.95 | I12: =Assumptions!H17 -> 0.95
B13: Effective gross income | D13: =D11*D12 -> 1490400 | E13: =E11*E12 -> 1739793.6 | F13: =F11*F12 -> 2031835.7 | G13: =G11*G12 -> 2092790.8 | H13: =H11*H12 -> 2155574.5 | I13: =I11*I12 -> 2220241.7
B14: Operating expenses | D14: =-D13*Assumptions!$C$14 -> -447120 | E14: =-E13*Assumptions!$C$14 -> -521938.08 | F14: =-F13*Assumptions!$C$14 -> -609550.7 | G14: =-G13*Assumptions!$C$14 -> -627837.23 | H14: =-H13*Assumptions!$C$14 -> -646672.34 | I14: =-I13*Assumptions!$C$14 -> -666072.51
B15: Net operating income | D15: =D13+D14 -> 1043280 | E15: =E13+E14 -> 1217855.5 | F15: =F13+F14 -> 1422285 | G15: =G13+G14 -> 1464953.5 | H15: =H13+H14 -> 1508902.1 | I15: =I13+I14 -> 1554169.2
B16: Renovation capex | D16: =-Assumptions!$C$8*(Assumptions!E16-Assumptions!D16) -> -1320000 | E16: =-Assumptions!$C$8*(Assumptions!F16-Assumptions!E16) -> -1320000
B18: ACQUISITION & DEBT
B19: Total acquisition cost (price + costs) | C19: =Assumptions!$C$6*(1+Assumptions!$C$7) -> 23100000
B20: Total project cost (incl. renovation) | C20: =C19+Assumptions!$C$8*Assumptions!$C$5 -> 25740000
B21: Senior loan drawn (60% LTC) | C21: =Assumptions!$C$20*C20 -> 15444000
B22: Equity required | C22: =C20-C21 -> 10296000
B24: Senior interest (Yr1-3) | D24: =-$C$21*Assumptions!$C$21 -> -926640 | E24: =-$C$21*Assumptions!$C$21 -> -926640 | F24: =-$C$21*Assumptions!$C$21 -> -926640
B25: Refinance (end Yr3)
B26: Stabilised value (Yr4 NOI / refi yield) | F26: =G15/Assumptions!$C$23 -> 30841127
B27: New loan (65% LTV) | F27: =F26*Assumptions!$C$24 -> 20046732
B28: Refi proceeds (new - old) | F28: =F27-C21 -> 4602732.5
B29: New loan interest (Yr4-5) | G29: =-$F$27*Assumptions!$C$25 -> -1152687.1 | H29: =-$F$27*Assumptions!$C$25 -> -1152687.1
B31: EXIT (Year 5)
B32: Exit value (Yr6 NOI / exit yield) | C32: =I15/Assumptions!$C$28 -> 34537093
B33: Less: selling costs | C33: =-C32*Assumptions!$C$29 -> -518056.4
B34: Net sale proceeds (property) | C34: =C32+C33 -> 34019037
B35: Less: repay refinance loan | C35: =-F27 -> -20046732
B36: Net sale proceeds to equity | C36: =C34+C35 -> 13972304
B38: RETURNS
B39: Unlevered cash flow (property) | C39: =-C19 -> -23100000 | D39: =D15+D16 -> -276720 | E39: =E15+E16 -> -102144.48 | F39: =F15 -> 1422285 | G39: =G15 -> 1464953.5 | H39: =H15+C34 -> 35527939
B40: Levered cash flow (equity) | C40: =-(C19-C21) -> -7656000 | D40: =D15+D24+D16 -> -1203360 | E40: =E15+E24+E16 -> -1028784.5 | F40: =F15+F24+F28 -> 5098377.4 | G40: =G15+G29 -> 312266.41 | H40: =H15+H29+C36 -> 14328519
B42: Unlevered IRR | C42: =IRR(C39:H39) -> 0.10662947
B43: Unlevered equity multiple | C43: =SUMIF(C39:H39,">0")/-SUMIF(C39:H39,"<0") -> 1.6361599
B44: Levered project IRR | C44: =IRR(C40:H40) -> 0.18345472
B45: Levered equity multiple | C45: =SUMIF(C40:H40,">0")/-SUMIF(C40:H40,"<0") -> 1.9962454
B46: Entry yield (Yr1 NOI / price) | C46: =D15/Assumptions!$C$6 -> 0.047421818
B47: Stabilised yield on cost (Yr3 NOI / cost) | C47: =F15/C20 -> 0.055255827

Sheet JV Waterfall
B1: PROJECT MERIDIAN | JV Distribution Waterfall
B3: LP 90% / GP 10%. Tiers: return of capital + 8% pref (pro-rata); 80/20 to 15% LP IRR; 70/30 above. Accrual-account method.
C4: Year 0 | D4: Year 1 | E4: Year 2 | F4: Year 3 | G4: Year 4 | H4: Year 5
B6: EQUITY CASH FLOW
B7: Total equity cash flow | C7: ='Property Model'!C40 -> -7656000 | D7: ='Property Model'!D40 -> -1203360 | E7: ='Property Model'!E40 -> -1028784.5 | F7: ='Property Model'!F40 -> 5098377.4 | G7: ='Property Model'!G40 -> 312266.41 | H7: ='Property Model'!H40 -> 14328519
B8: LP contribution | C8: =IF(C7<0,Assumptions!$C$32*-C7,0) -> 6890400 | D8: =IF(D7<0,Assumptions!$C$32*-D7,0) -> 1083024 | E8: =IF(E7<0,Assumptions!$C$32*-E7,0) -> 925906.03 | F8: =IF(F7<0,Assumptions!$C$32*-F7,0) -> 0 | G8: =IF(G7<0,Assumptions!$C$32*-G7,0) -> 0 | H8: =IF(H7<0,Assumptions!$C$32*-H7,0) -> 0
B9: GP contribution | C9: =IF(C7<0,Assumptions!$C$33*-C7,0) -> 765600 | D9: =IF(D7<0,Assumptions!$C$33*-D7,0) -> 120336 | E9: =IF(E7<0,Assumptions!$C$33*-E7,0) -> 102878.45 | F9: =IF(F7<0,Assumptions!$C$33*-F7,0) -> 0 | G9: =IF(G7<0,Assumptions!$C$33*-G7,0) -> 0 | H9: =IF(H7<0,Assumptions!$C$33*-H7,0) -> 0
B10: Distributable cash | C10: =IF(C7>0,C7,0) -> 0 | D10: =IF(D7>0,D7,0) -> 0 | E10: =IF(E7>0,E7,0) -> 0 | F10: =IF(F7>0,F7,0) -> 5098377.4 | G10: =IF(G7>0,G7,0) -> 312266.41 | H10: =IF(H7>0,H7,0) -> 14328519
B12: WATERFALL ALLOCATION
B13: LP cap+pref — opening | C13: 0 | D13: =C22 -> 6890400 | E13: =D22 -> 8524656 | F13: =E22 -> 10132535 | G13: =F22 -> 6354597.6 | H13: =G22 -> 6581925.6
B14: LP cap+pref — bal (accr 8% + contrib) | C14: =C13*(1+Assumptions!$C$34)+C8 -> 6890400 | D14: =D13*(1+Assumptions!$C$34)+D8 -> 8524656 | E14: =E13*(1+Assumptions!$C$34)+E8 -> 10132535 | F14: =F13*(1+Assumptions!$C$34)+F8 -> 10943137 | G14: =G13*(1+Assumptions!$C$34)+G8 -> 6862965.4 | H14: =H13*(1+Assumptions!$C$34)+H8 -> 7108479.7
B15: GP cap+pref — opening | C15: 0 | D15: =C23 -> 765600 | E15: =D23 -> 947184 | F15: =E23 -> 1125837.2 | G15: =F23 -> 706066.4 | H15: =G23 -> 731325.07
B16: GP cap+pref — bal (accr 8% + contrib) | C16: =C15*(1+Assumptions!$C$34)+C9 -> 765600 | D16: =D15*(1+Assumptions!$C$34)+D9 -> 947184 | E16: =E15*(1+Assumptions!$C$34)+E9 -> 1125837.2 | F16: =F15*(1+Assumptions!$C$34)+F9 -> 1215904.1 | G16: =G15*(1+Assumptions!$C$34)+G9 -> 762551.71 | H16: =H15*(1+Assumptions!$C$34)+H9 -> 789831.08
B17: Tier 1 need (LP+GP bal) | C17: =C14+C16 -> 7656000 | D17: =D14+D16 -> 9471840 | E17: =E14+E16 -> 11258372 | F17: =F14+F16 -> 12159041 | G17: =G14+G16 -> 7625517.1 | H17: =H14+H16 -> 7898310.8
B18: Tier 1 paid (min cash, need) | C18: =MIN(C10,C17) -> 0 | D18: =MIN(D10,D17) -> 0 | E18: =MIN(E10,E17) -> 0 | F18: =MIN(F10,F17) -> 5098377.4 | G18: =MIN(G10,G17) -> 312266.41 | H18: =MIN(H10,H17) -> 7898310.8
B19: Tier 1 to LP | C19: =IF(C17>0,C18*C14/C17,0) -> 0 | D19: =IF(D17>0,D18*D14/D17,0) -> 0 | E19: =IF(E17>0,E18*E14/E17,0) -> 0 | F19: =IF(F17>0,F18*F14/F17,0) -> 4588539.7 | G19: =IF(G17>0,G18*G14/G17,0) -> 281039.77 | H19: =IF(H17>0,H18*H14/H17,0) -> 7108479.7
B20: Tier 1 to GP | C20: =C18-C19 -> 0 | D20: =D18-D19 -> 0 | E20: =E18-E19 -> 0 | F20: =F18-F19 -> 509837.74 | G20: =G18-G19 -> 31226.641 | H20: =H18-H19 -> 789831.08
B21: Cash after Tier 1 | C21: =C10-C18 -> 0 | D21: =D10-D18 -> 0 | E21: =E10-E18 -> 0 | F21: =F10-F18 -> 0 | G21: =G10-G18 -> 0 | H21: =H10-H18 -> 6430208.6
B22: LP cap+pref — closing | C22: =C14-C19 -> 6890400 | D22: =D14-D19 -> 8524656 | E22: =E14-E19 -> 10132535 | F22: =F14-F19 -> 6354597.6 | G22: =G14-G19 -> 6581925.6 | H22: =H14-H19 -> 0
B23: GP cap+pref — closing | C23: =C16-C20 -> 765600 | D23: =D16-D20 -> 947184 | E23: =E16-E20 -> 1125837.2 | F23: =F16-F20 -> 706066.4 | G23: =G16-G20 -> 731325.07 | H23: =H16-H20 -> 0
B24: LP 15% acct — opening | C24: 0 | D24: =C31 -> 6890400 | E24: =D31 -> 9006984 | F24: =E31 -> 11283938 | G24: =F31 -> 8387988.6 | H24: =G31 -> 9365147.1
B25: LP 15% acct — bal (accr 15% + contrib - T1 LP) | C25: =C24*(1+Assumptions!$C$35)+C8-C19 -> 6890400 | D25: =D24*(1+Assumptions!$C$35)+D8-D19 -> 9006984 | E25: =E24*(1+Assumptions!$C$35)+E8-E19 -> 11283938 | F25: =F24*(1+Assumptions!$C$35)+F8-F19 -> 8387988.6 | G25: =G24*(1+Assumptions!$C$35)+G8-G19 -> 9365147.1 | H25: =H24*(1+Assumptions!$C$35)+H8-H19 -> 3661439.5
B26: Tier 2 need (bal / 80%) | C26: =MAX(0,C25)/0.8 -> 8613000 | D26: =MAX(0,D25)/0.8 -> 11258730 | E26: =MAX(0,E25)/0.8 -> 14104922 | F26: =MAX(0,F25)/0.8 -> 10484986 | G26: =MAX(0,G25)/0.8 -> 11706434 | H26: =MAX(0,H25)/0.8 -> 4576799.4
B27: Tier 2 paid (min, need) | C27: =MIN(C21,C26) -> 0 | D27: =MIN(D21,D26) -> 0 | E27: =MIN(E21,E26) -> 0 | F27: =MIN(F21,F26) -> 0 | G27: =MIN(G21,G26) -> 0 | H27: =MIN(H21,H26) -> 4576799.4
B28: Tier 2 to LP (80%) | C28: =C27*0.8 -> 0 | D28: =D27*0.8 -> 0 | E28: =E27*0.8 -> 0 | F28: =F27*0.8 -> 0 | G28: =G27*0.8 -> 0 | H28: =H27*0.8 -> 3661439.5
B29: Tier 2 to GP (20%) | C29: =C27*0.2 -> 0 | D29: =D27*0.2 -> 0 | E29: =E27*0.2 -> 0 | F29: =F27*0.2 -> 0 | G29: =G27*0.2 -> 0 | H29: =H27*0.2 -> 915359.88
B30: Cash after Tier 2 | C30: =C21-C27 -> 0 | D30: =D21-D27 -> 0 | E30: =E21-E27 -> 0 | F30: =F21-F27 -> 0 | G30: =G21-G27 -> 0 | H30: =H21-H27 -> 1853409.3
B31: LP 15% acct — closing | C31: =C25-C28 -> 6890400 | D31: =D25-D28 -> 9006984 | E31: =E25-E28 -> 11283938 | F31: =F25-F28 -> 8387988.6 | G31: =G25-G28 -> 9365147.1 | H31: =H25-H28 -> 0
B32: Tier 3 paid (remainder) | C32: =C30 -> 0 | D32: =D30 -> 0 | E32: =E30 -> 0 | F32: =F30 -> 0 | G32: =G30 -> 0 | H32: =H30 -> 1853409.3
B33: Tier 3 to LP (70%) | C33: =C32*0.7 -> 0 | D33: =D32*0.7 -> 0 | E33: =E32*0.7 -> 0 | F33: =F32*0.7 -> 0 | G33: =G32*0.7 -> 0 | H33: =H32*0.7 -> 1297386.5
B34: Tier 3 to GP (30%) | C34: =C32*0.3 -> 0 | D34: =D32*0.3 -> 0 | E34: =E32*0.3 -> 0 | F34: =F32*0.3 -> 0 | G34: =G32*0.3 -> 0 | H34: =H32*0.3 -> 556022.78
B35: LP distribution (total) | C35: =C19+C28+C33 -> 0 | D35: =D19+D28+D33 -> 0 | E35: =E19+E28+E33 -> 0 | F35: =F19+F28+F33 -> 4588539.7 | G35: =G19+G28+G33 -> 281039.77 | H35: =H19+H28+H33 -> 12067306
B36: GP distribution (total) | C36: =C20+C29+C34 -> 0 | D36: =D20+D29+D34 -> 0 | E36: =E20+E29+E34 -> 0 | F36: =F20+F29+F34 -> 509837.74 | G36: =G20+G29+G34 -> 31226.641 | H36: =H20+H29+H34 -> 2261213.7
B37: LP net cash flow | C37: =-C8+C35 -> -6890400 | D37: =-D8+D35 -> -1083024 | E37: =-E8+E35 -> -925906.03 | F37: =-F8+F35 -> 4588539.7 | G37: =-G8+G35 -> 281039.77 | H37: =-H8+H35 -> 12067306
B38: GP net cash flow | C38: =-C9+C36 -> -765600 | D38: =-D9+D36 -> -120336 | E38: =-E9+E36 -> -102878.45 | F38: =-F9+F36 -> 509837.74 | G38: =-G9+G36 -> 31226.641 | H38: =-H9+H36 -> 2261213.7
B40: PARTNER RETURNS
B41: LP IRR | C41: =IRR(C37:H37) -> 0.17090268
B42: LP equity multiple | C42: =SUM(D35:H35)/SUM(C8:H8) -> 1.9031641
B43: GP IRR | C43: =IRR(C38:H38) -> 0.27684092
B44: GP equity multiple | C44: =SUM(D36:H36)/SUM(C9:H9) -> 2.8339777
...

Sheet IC Summary
B1: PROJECT MERIDIAN | Investment Committee Summary | L1: Strictly Confidential
B3: 120-unit value-add multifamily (BTR) · UK regional city · 5-year hold · JV with promote (illustrative work sample)
B4: Recommendation: proceed — buy at £22.0m, renovate to institutional BTR, refinance Yr3, exit Yr5.
B6: SOURCES & USES | H6: BUSINESS PLAN
B7: Purchase price | E7: =Assumptions!$C$6 -> 22000000 | H7: Units / price per unit | K7: 120 / £183k
B8: Acquisition costs | E8: =Assumptions!$C$6*Assumptions!$C$7 -> 1100000 | H8: In-place → renovated rent | K8: £1,150 → £1,400/mo
B9: Renovation capex | E9: =Assumptions!$C$8*Assumptions!$C$5 -> 2640000 | H9: Renovation | K9: £22k/unit, phased over 24 mo
B10: Total project cost | E10: ='Property Model'!C20 -> 25740000 | H10: Occupancy | K10: 90% → 95% stabilised
B11: Senior debt (60% LTC) | E11: ='Property Model'!C21 -> 15444000 | H11: Refinance | K11: Yr3 at 4.75% yield, 65% LTV
B12: Equity | E12: ='Property Model'!C22 -> 10296000 | H12: Exit | K12: Yr5 at 4.50% cap rate
B14: RETURNS
C15: Property | E15: LP (90%) | G15: GP (10%)
B16: IRR | C16: ='Property Model'!C44 -> 0.18345472 | E16: ='JV Waterfall'!C41 -> 0.17090268 | G16: ='JV Waterfall'!C43 -> 0.27684092
B17: Equity multiple | C17: ='Property Model'!C45 -> 1.9962454 | E17: ='JV Waterfall'!C42 -> 1.9031641 | G17: ='JV Waterfall'!C44 -> 2.8339777
B18: Unlevered IRR / GP promote (£) | C18: ='Property Model'!C42 -> 0.10662947 | G18: ='JV Waterfall'!C45 -> 828361.79
B20: SENSITIVITY — levered project IRR vs exit yield
B21: Exit yield | C21: 0.04 | D21: 0.0425 | E21: 0.045 | F21: 0.0475 | G21: 0.05
B22: Levered IRR | C22: =IRR(C40:C45) -> 0.2351091 | D22: =IRR(D40:D45) -> 0.20893388 | E22: =IRR(E40:E45) -> 0.18345472 | F22: =IRR(F40:F45) -> 0.15848139 | G22: =IRR(G40:G45) -> 0.1338345
B24: RECOMMENDATION & RISKS
B25: 1. Base case delivers a project IRR of ~18% (2.0x), an LP IRR of ~17% (1.9x) and a GP IRR of ~28% (2.8x) — a compelling value-add that clears the 8% preferred and the 15% second hurdle, activating the full two-tier promote.
B26: 2. Value is created by renovating to a £250/month rent premium and re-rating the asset; a Year-3 refinance returns ~£4.6m of capital to investors, de-risking the equity ahead of exit.
B27: 3. Key risks: exit-yield movement (the return is most sensitive to the exit cap rate — see table), renovation cost / timing overrun, and slower lease-up. A +25bps exit yield still leaves the deal comfortably above hurdle.
B28: 4. Recommendation: approve the acquisition at £22.0m and the JV terms as structured.
B40: (sensitivity working) | C40: ='Property Model'!C40 -> -7656000 | D40: ='Property Model'!C40 -> -7656000 | E40: ='Property Model'!C40 -> -7656000 | F40: ='Property Model'!C40 -> -7656000 | G40: ='Property Model'!C40 -> -7656000
C41: ='Property Model'!D40 -> -1203360 | D41: ='Property Model'!D40 -> -1203360 | E41: ='Property Model'!D40 -> -1203360 | F41: ='Property Model'!D40 -> -1203360 | G41: ='Property Model'!D40 -> -1203360
C42: ='Property Model'!E40 -> -1028784.5 | D42: ='Property Model'!E40 -> -1028784.5 | E42: ='Property Model'!E40 -> -1028784.5 | F42: ='Property Model'!E40 -> -1028784.5 | G42: ='Property Model'!E40 -> -1028784.5
C43: ='Property Model'!F40 -> 5098377.4 | D43: ='Property Model'!F40 -> 5098377.4 | E43: ='Property Model'!F40 -> 5098377.4 | F43: ='Property Model'!F40 -> 5098377.4 | G43: ='Property Model'!F40 -> 5098377.4
C44: ='Property Model'!G40 -> 312266.41 | D44: ='Property Model'!G40 -> 312266.41 | E44: ='Property Model'!G40 -> 312266.41 | F44: ='Property Model'!G40 -> 312266.41 | G44: ='Property Model'!G40 -> 312266.41
C45: =('Property Model'!H15+'Property Model'!H29+('Property Model'!I15/0.04*(1-Assumptions!$C$29)-'Property Model'!F27)) -> 18580899 | D45: =('Property Model'!H15+'Property Model'!H29+('Property Model'!I15/0.0425*(1-Assumptions!$C$29)-'Property Model'!F27)) -> 16329639 | E45: =('Property Model'!H15+'Property Model'!H29+('Property Model'!I15/0.045*(1-Assumptions!$C$29)-'Property Model'!F27)) -> 14328519 | F45: =('Property Model'!H15+'Property Model'!H29+('Property Model'!I15/0.0475*(1-Assumptions!$C$29)-'Property Model'!F27)) -> 12538044 | G45: =('Property Model'!H15+'Property Model'!H29+('Property Model'!I15/0.05*(1-Assumptions!$C$29)-'Property Model'!F27)) -> 10926616
